<sdf version='1.7'>
  <world name='default'>
    <light name='sun' type='directional'>
      <cast_shadows>1</cast_shadows>
      <pose>0 0 10 0 -0 0</pose>
      <diffuse>0.8 0.8 0.8 1</diffuse>
      <specular>0.2 0.2 0.2 1</specular>
      <attenuation>
        <range>1000</range>
        <constant>0.9</constant>
        <linear>0.01</linear>
        <quadratic>0.001</quadratic>
      </attenuation>
      <direction>-0.5 0.1 -0.9</direction>
      <spot>
        <inner_angle>0</inner_angle>
        <outer_angle>0</outer_angle>
        <falloff>0</falloff>
      </spot>
    </light>
    <model name='ground_plane'>
      <static>1</static>
      <link name='link'>
        <collision name='collision'>
          <geometry>
            <plane>
              <normal>0 0 1</normal>
              <size>100 100</size>
            </plane>
          </geometry>
          <surface>
            <friction>
              <ode>
                <mu>100</mu>
                <mu2>50</mu2>
              </ode>
              <torsional>
                <ode/>
              </torsional>
            </friction>
            <contact>
              <ode/>
            </contact>
            <bounce/>
          </surface>
          <max_contacts>10</max_contacts>
        </collision>
        <visual name='visual'>
          <cast_shadows>0</cast_shadows>
          <geometry>
            <plane>
              <normal>0 0 1</normal>
              <size>100 100</size>
            </plane>
          </geometry>
          <material>
            <script>
              <uri>file://media/materials/scripts/gazebo.material</uri>
              <name>Gazebo/Grey</name>
            </script>
          </material>
        </visual>
        <self_collide>0</self_collide>
        <enable_wind>0</enable_wind>
        <kinematic>0</kinematic>
      </link>
    </model>
    <gravity>0 0 -9.8</gravity>
    <magnetic_field>6e-06 2.3e-05 -4.2e-05</magnetic_field>
    <atmosphere type='adiabatic'/>
    <physics type='ode'>
      <max_step_size>0.001</max_step_size>
      <real_time_factor>1</real_time_factor>
      <real_time_update_rate>1000</real_time_update_rate>
    </physics>
    <scene>
      <ambient>0.4 0.4 0.4 1</ambient>
      <background>0.7 0.7 0.7 1</background>
      <shadows>1</shadows>
    </scene>
    <wind/>
    <spherical_coordinates>
      <surface_model>EARTH_WGS84</surface_model>
      <latitude_deg>0</latitude_deg>
      <longitude_deg>0</longitude_deg>
      <elevation>0</elevation>
      <heading_deg>0</heading_deg>
    </spherical_coordinates>
    <state world_name='default'>
      <sim_time>377 101000000</sim_time>
      <real_time>31 441205662</real_time>
      <wall_time>1716802773 950020270</wall_time>
      <iterations>31130</iterations>
      <model name='Robot1'>
        <pose>0.60037 6.00006 0.007548 -0.000403 -0.000481 1.56981</pose>
        <scale>1 1 1</scale>
        <link name='base_link'>
          <pose>0.60037 6.00006 0.007548 -0.000403 -0.000481 1.56981</pose>
          <velocity>0 -1e-06 1.4e-05 0.000136 0 -1e-06</velocity>
          <acceleration>-0 0 0 0 -0 0</acceleration>
          <wrench>-0 0 0 0 -0 0</wrench>
        </link>
        <link name='left_wheel'>
          <pose>0.715359 5.99994 0.035094 0.009926 -0.000481 1.56981</pose>
          <velocity>0 -5e-06 1.4e-05 0.000136 2e-06 -1e-06</velocity>
          <acceleration>-0 -0 -0 -1e-06 -0 -1e-06</acceleration>
          <wrench>-0 -0 -0 0 -0 0</wrench>
        </link>
        <link name='right_wheel'>
          <pose>0.485359 6.00016 0.035002 -0.000301 -0.00048 1.56981</pose>
          <velocity>0 -5e-06 1.4e-05 0.000136 3e-06 -1e-06</velocity>
          <acceleration>-0 -0 0 -1e-06 -0 1e-06</acceleration>
          <wrench>-0 -0 0 0 -0 0</wrench>
        </link>
      </model>
      <model name='Robot2'>
        <pose>0.379927 -0.000324 0.007839 0.157147 -0 1.57417</pose>
        <scale>1 1 1</scale>
        <link name='base_link'>
          <pose>0.379927 -0.000324 0.007839 0.157147 -0 1.57417</pose>
          <velocity>-9.8e-05 -0 -5.4e-05 4.2e-05 -0.012544 0</velocity>
          <acceleration>0.193074 0.000651 -0.0162 3.12723 0.38932 3.12364</acceleration>
          <wrench>0.699701 0.00236 -0.058708 0 -0 0</wrench>
        </link>
        <link name='left_wheel'>
          <pose>0.497813 7.4e-05 0.017002 -1.77811 0 1.57417</pose>
          <velocity>-0.000188 0 0.00142 6.4e-05 -0.012544 -1.6e-05</velocity>
          <acceleration>0.036574 -6.1e-05 -0.285472 3.11786 0.618319 3.14084</acceleration>
          <wrench>0.018287 -3e-05 -0.142736 0 -0 0</wrench>
        </link>
        <link name='right_wheel'>
          <pose>0.270648 -0.000692 0.052998 -1.60453 -0 1.57417</pose>
          <velocity>-0.000666 -2e-06 -0.001424 4.2e-05 -0.012544 -1e-06</velocity>
          <acceleration>0.134081 0.000426 0.286442 3.13312 0.618267 -3.1415</acceleration>
          <wrench>0.06704 0.000213 0.143221 0 -0 0</wrench>
        </link>
      </model>
      <model name='ground_plane'>
        <pose>0 0 0 0 -0 0</pose>
        <scale>1 1 1</scale>
        <link name='link'>
          <pose>0 0 0 0 -0 0</pose>
          <velocity>0 0 0 0 -0 0</velocity>
          <acceleration>0 0 0 0 -0 0</acceleration>
          <wrench>0 0 0 0 -0 0</wrench>
        </link>
      </model>
      <model name='unit_box'>
        <pose>1.5 -0.3 0 0 -0 0</pose>
        <scale>1 1 1</scale>
        <link name='link_1'>
          <pose>1.44038 -0.137721 2e-06 1e-05 -0 0</pose>
          <velocity>0 0 0 0 -0 0</velocity>
          <acceleration>0 0 0 0 -0 0</acceleration>
          <wrench>0 0 0 0 -0 0</wrench>
        </link>
      </model>
      <light name='sun'>
        <pose>0 0 10 0 -0 0</pose>
      </light>
    </state>
    <model name='unit_box'>
      <link name='link_1'>
        <inertial>
          <mass>1</mass>
          <inertia>
            <ixx>0.166667</ixx>
            <ixy>0</ixy>
            <ixz>0</ixz>
            <iyy>0.166667</iyy>
            <iyz>0</iyz>
            <izz>0.166667</izz>
          </inertia>
          <pose>0 0 0 0 -0 0</pose>
        </inertial>
        <pose>-0.05962 0.162279 2e-06 1e-05 -0 0</pose>
        <visual name='visual'>
          <pose>0 0 0 0 -0 0</pose>
          <geometry>
            <mesh>
              <uri>/home/ubuntu/Downloads/Map(1).stl</uri>
              <scale>1 1 1</scale>
            </mesh>
          </geometry>
          <material>
            <lighting>1</lighting>
            <script>
              <uri>file://media/materials/scripts/gazebo.material</uri>
              <name>Gazebo/Grey</name>
            </script>
            <shader type='pixel'/>
          </material>
          <transparency>0</transparency>
          <cast_shadows>1</cast_shadows>
        </visual>
        <collision name='collision'>
          <laser_retro>0</laser_retro>
          <max_contacts>10</max_contacts>
          <pose>0 0 0 0 -0 0</pose>
          <geometry>
            <mesh>
              <uri>/home/ubuntu/Downloads/Map(1).stl</uri>
              <scale>1 1 1</scale>
            </mesh>
          </geometry>
          <surface>
            <friction>
              <ode>
                <mu>1</mu>
                <mu2>1</mu2>
                <fdir1>0 0 0</fdir1>
                <slip1>0</slip1>
                <slip2>0</slip2>
              </ode>
              <torsional>
                <coefficient>1</coefficient>
                <patch_radius>0</patch_radius>
                <surface_radius>0</surface_radius>
                <use_patch_radius>1</use_patch_radius>
                <ode>
                  <slip>0</slip>
                </ode>
              </torsional>
            </friction>
            <bounce>
              <restitution_coefficient>0</restitution_coefficient>
              <threshold>1e+06</threshold>
            </bounce>
            <contact>
              <collide_without_contact>0</collide_without_contact>
              <collide_without_contact_bitmask>1</collide_without_contact_bitmask>
              <collide_bitmask>1</collide_bitmask>
              <ode>
                <soft_cfm>0</soft_cfm>
                <soft_erp>0.2</soft_erp>
                <kp>1e+13</kp>
                <kd>1</kd>
                <max_vel>0.01</max_vel>
                <min_depth>0</min_depth>
              </ode>
              <bullet>
                <split_impulse>1</split_impulse>
                <split_impulse_penetration_threshold>-0.01</split_impulse_penetration_threshold>
                <soft_cfm>0</soft_cfm>
                <soft_erp>0.2</soft_erp>
                <kp>1e+13</kp>
                <kd>1</kd>
              </bullet>
            </contact>
          </surface>
        </collision>
        <self_collide>0</self_collide>
        <enable_wind>0</enable_wind>
        <kinematic>0</kinematic>
      </link>
      <static>1</static>
      <allow_auto_disable>1</allow_auto_disable>
      <pose>0 0 0 0 -0 0</pose>
    </model>
    <gui fullscreen='0'>
      <camera name='user_camera'>
        <pose>3.41718 -1.85069 2.64086 0 0.275643 2.35619</pose>
        <view_controller>orbit</view_controller>
        <projection_type>perspective</projection_type>
      </camera>
    </gui>
    <model name='Robot1'>
      <link name='base_link'>
        <inertial>
          <pose>-0.002373 0.00016 0.069509 0 -0 0</pose>
          <mass>3.624</mass>
          <inertia>
            <ixx>0.0529466</ixx>
            <ixy>-3.03764e-05</ixy>
            <ixz>0.000688519</ixz>
            <iyy>0.0577457</iyy>
            <iyz>2.29154e-05</iyz>
            <izz>0.0998172</izz>
          </inertia>
        </inertial>
        <collision name='base_link_fixed_joint_lump__base_footprint_collision'>
          <pose>0 0 0.07 0 -0 0</pose>
          <geometry>
            <cylinder>
              <length>0.11</length>
              <radius>0.125</radius>
            </cylinder>
          </geometry>
          <max_contacts>10</max_contacts>
          <surface>
            <contact>
              <ode/>
            </contact>
            <bounce/>
            <friction>
              <torsional>
                <ode/>
              </torsional>
              <ode/>
            </friction>
          </surface>
        </collision>
        <collision name='base_link_fixed_joint_lump__ball_1_collision_1'>
          <pose>-0.1 0 0.0275 0 -0 0</pose>
          <geometry>
            <sphere>
              <radius>0.035</radius>
            </sphere>
          </geometry>
          <max_contacts>10</max_contacts>
          <surface>
            <contact>
              <ode/>
            </contact>
            <bounce/>
            <friction>
              <torsional>
                <ode/>
              </torsional>
              <ode/>
            </friction>
          </surface>
        </collision>
        <collision name='base_link_fixed_joint_lump__ball_2_collision_2'>
          <pose>0.1 0 0.0275 0 -0 0</pose>
          <geometry>
            <sphere>
              <radius>0.035</radius>
            </sphere>
          </geometry>
          <max_contacts>10</max_contacts>
          <surface>
            <contact>
              <ode/>
            </contact>
            <bounce/>
            <friction>
              <torsional>
                <ode/>
              </torsional>
              <ode/>
            </friction>
          </surface>
        </collision>
        <collision name='base_link_fixed_joint_lump__imu_collision_3'>
          <pose>0.05 0.058 0.03 0 -0 0</pose>
          <geometry>
            <box>
              <size>0.006 0.004 0.008</size>
            </box>
          </geometry>
          <max_contacts>10</max_contacts>
          <surface>
            <contact>
              <ode/>
            </contact>
            <bounce/>
            <friction>
              <torsional>
                <ode/>
              </torsional>
              <ode/>
            </friction>
          </surface>
        </collision>
        <collision name='base_link_fixed_joint_lump__marvelmind_collision_4'>
          <pose>-0.091 0 0.143 0 -0 0</pose>
          <geometry>
            <box>
              <size>0.06 0.06 0.03</size>
            </box>
          </geometry>
          <max_contacts>10</max_contacts>
          <surface>
            <contact>
              <ode/>
            </contact>
            <bounce/>
            <friction>
              <torsional>
                <ode/>
              </torsional>
              <ode/>
            </friction>
          </surface>
        </collision>
        <collision name='base_link_fixed_joint_lump__lidar_link_collision_5'>
          <pose>0 0 0.143 0 -0 1.5708</pose>
          <geometry>
            <cylinder>
              <length>0.18</length>
              <radius>0.0508</radius>
            </cylinder>
          </geometry>
          <max_contacts>10</max_contacts>
          <surface>
            <contact>
              <ode/>
            </contact>
            <bounce/>
            <friction>
              <torsional>
                <ode/>
              </torsional>
              <ode/>
            </friction>
          </surface>
        </collision>
        <visual name='base_link_fixed_joint_lump__base_footprint_visual'>
          <pose>0 0 0.07 0 -0 0</pose>
          <geometry>
            <cylinder>
              <length>0.11</length>
              <radius>0.125</radius>
            </cylinder>
          </geometry>
        </visual>
        <visual name='base_link_fixed_joint_lump__ball_1_visual_1'>
          <pose>-0.1 0 0.0275 1.5707 -0 0</pose>
          <geometry>
            <sphere>
              <radius>0.035</radius>
            </sphere>
          </geometry>
        </visual>
        <visual name='base_link_fixed_joint_lump__ball_2_visual_2'>
          <pose>0.1 0 0.0275 1.5707 -0 0</pose>
          <geometry>
            <sphere>
              <radius>0.035</radius>
            </sphere>
          </geometry>
        </visual>
        <visual name='base_link_fixed_joint_lump__imu_visual_3'>
          <pose>0.05 0.058 0.03 0 -0 0</pose>
          <geometry>
            <box>
              <size>0.0038 0.0052 0.00113</size>
            </box>
          </geometry>
        </visual>
        <visual name='base_link_fixed_joint_lump__marvelmind_visual_4'>
          <pose>-0.091 0 0.143 0 -0 0</pose>
          <geometry>
            <box>
              <size>0.06 0.06 0.03</size>
            </box>
          </geometry>
        </visual>
        <visual name='base_link_fixed_joint_lump__lidar_link_visual_5'>
          <pose>0 0 0.143 0 -0 1.5708</pose>
          <geometry>
            <cylinder>
              <length>0.18</length>
              <radius>0.0508</radius>
            </cylinder>
          </geometry>
        </visual>
        <self_collide>0</self_collide>
        <enable_wind>0</enable_wind>
        <kinematic>0</kinematic>
      </link>
      <joint name='joint_wheel_left' type='revolute'>
        <pose relative_to='base_link'>0 -0.115 0.0275 0 -0 0</pose>
        <parent>base_link</parent>
        <child>left_wheel</child>
        <axis>
          <xyz>1 0 0</xyz>
          <limit>
            <lower>-1e+16</lower>
            <upper>1e+16</upper>
          </limit>
          <dynamics>
            <spring_reference>0</spring_reference>
            <spring_stiffness>0</spring_stiffness>
          </dynamics>
        </axis>
      </joint>
      <link name='left_wheel'>
        <pose relative_to='joint_wheel_left'>0 0 0 0 -0 0</pose>
        <inertial>
          <pose>0 0 0 0 -0 0</pose>
          <mass>0.5</mass>
          <inertia>
            <ixx>0.0008</ixx>
            <ixy>0</ixy>
            <ixz>0</ixz>
            <iyy>0.0008</iyy>
            <iyz>0</iyz>
            <izz>0.000266</izz>
          </inertia>
        </inertial>
        <collision name='left_wheel_collision'>
          <pose>0 0 0 1.5707 -0 0</pose>
          <geometry>
            <cylinder>
              <length>0.02</length>
              <radius>0.035</radius>
            </cylinder>
          </geometry>
          <surface>
            <contact>
              <ode>
                <kp>1e+07</kp>
                <kd>1</kd>
              </ode>
            </contact>
            <friction>
              <ode>
                <mu>200</mu>
                <mu2>100</mu2>
                <fdir1>1 0 0</fdir1>
              </ode>
              <torsional>
                <ode/>
              </torsional>
            </friction>
            <bounce/>
          </surface>
          <max_contacts>10</max_contacts>
        </collision>
        <visual name='left_wheel_visual'>
          <pose>0 0 0 1.5707 -0 0</pose>
          <geometry>
            <cylinder>
              <length>0.02</length>
              <radius>0.035</radius>
            </cylinder>
          </geometry>
          <material>
            <script>
              <name>Gazebo/Black</name>
              <uri>file://media/materials/scripts/gazebo.material</uri>
            </script>
          </material>
        </visual>
        <self_collide>0</self_collide>
        <enable_wind>0</enable_wind>
        <kinematic>0</kinematic>
      </link>
      <joint name='joint_wheel_right' type='revolute'>
        <pose relative_to='base_link'>0 0.115 0.0275 0 -0 0</pose>
        <parent>base_link</parent>
        <child>right_wheel</child>
        <axis>
          <xyz>1 0 0</xyz>
          <limit>
            <lower>-1e+16</lower>
            <upper>1e+16</upper>
          </limit>
          <dynamics>
            <spring_reference>0</spring_reference>
            <spring_stiffness>0</spring_stiffness>
          </dynamics>
        </axis>
      </joint>
      <link name='right_wheel'>
        <pose relative_to='joint_wheel_right'>0 0 0 0 -0 0</pose>
        <inertial>
          <pose>0 0 0 0 -0 0</pose>
          <mass>0.5</mass>
          <inertia>
            <ixx>0.0008</ixx>
            <ixy>0</ixy>
            <ixz>0</ixz>
            <iyy>0.0008</iyy>
            <iyz>0</iyz>
            <izz>0.000266</izz>
          </inertia>
        </inertial>
        <collision name='right_wheel_collision'>
          <pose>0 0 0 1.5707 -0 0</pose>
          <geometry>
            <cylinder>
              <length>0.02</length>
              <radius>0.035</radius>
            </cylinder>
          </geometry>
          <surface>
            <contact>
              <ode>
                <kp>1e+07</kp>
                <kd>1</kd>
              </ode>
            </contact>
            <friction>
              <ode>
                <mu>200</mu>
                <mu2>100</mu2>
                <fdir1>1 0 0</fdir1>
              </ode>
              <torsional>
                <ode/>
              </torsional>
            </friction>
            <bounce/>
          </surface>
          <max_contacts>10</max_contacts>
        </collision>
        <visual name='right_wheel_visual'>
          <pose>0 0 0 1.5707 -0 0</pose>
          <geometry>
            <cylinder>
              <length>0.02</length>
              <radius>0.035</radius>
            </cylinder>
          </geometry>
          <material>
            <script>
              <name>Gazebo/Black</name>
              <uri>file://media/materials/scripts/gazebo.material</uri>
            </script>
          </material>
        </visual>
        <self_collide>0</self_collide>
        <enable_wind>0</enable_wind>
        <kinematic>0</kinematic>
      </link>
      <plugin name='gazebo_ros_diff_drive' filename='libgazebo_ros_diff_drive.so'>
        <alwaysOn>1</alwaysOn>
        <updateRate>10</updateRate>
        <max_wheel_torque>100</max_wheel_torque>
        <left_joint>joint_wheel_left</left_joint>
        <right_joint>joint_wheel_right</right_joint>
        <wheel_separation>0.0955</wheel_separation>
        <wheel_diameter>0.044</wheel_diameter>
        <command_topic>cmd_vel</command_topic>
        <publish_odom>1</publish_odom>
        <publish_odom_tf>1</publish_odom_tf>
        <publish_wheel_tf>1</publish_wheel_tf>
        <odometry_topic>odom</odometry_topic>
        <odometry_frame>odom</odometry_frame>
        <robot_base_frame>base_link</robot_base_frame>
        <ros>
          <namespace>Robot1</namespace>
        </ros>
      </plugin>
      <frame name='joint_ball_1' attached_to='base_footprint'>
        <pose>-0.1 0 -0.0425 0 -0 0</pose>
      </frame>
      <frame name='ball_1' attached_to='joint_ball_1'/>
      <frame name='joint_ball_2' attached_to='base_footprint'>
        <pose>0.1 0 -0.0425 0 -0 0</pose>
      </frame>
      <frame name='ball_2' attached_to='joint_ball_2'/>
      <frame name='joint_imu' attached_to='base_footprint'>
        <pose>0.05 0.058 -0.04 0 -0 0</pose>
      </frame>
      <frame name='imu' attached_to='joint_imu'/>
      <frame name='joint_base_link' attached_to='base_link'>
        <pose>0 0 0.07 0 -0 0</pose>
      </frame>
      <frame name='base_footprint' attached_to='joint_base_link'/>
      <frame name='joint_marv' attached_to='base_link'>
        <pose>-0.091 0 0.143 0 -0 0</pose>
      </frame>
      <frame name='marvelmind' attached_to='joint_marv'/>
      <frame name='lidar_joint' attached_to='base_link'>
        <pose>0 0 0.143 0 -0 1.5708</pose>
      </frame>
      <frame name='lidar_link' attached_to='lidar_joint'/>
      <pose>0.6 6 0 0 -0 1.5707</pose>
    </model>
    <model name='Robot2'>
      <link name='base_link'>
        <inertial>
          <pose>-0.002373 0.00016 0.069509 0 -0 0</pose>
          <mass>3.624</mass>
          <inertia>
            <ixx>0.0529466</ixx>
            <ixy>-3.03764e-05</ixy>
            <ixz>0.000688519</ixz>
            <iyy>0.0577457</iyy>
            <iyz>2.29154e-05</iyz>
            <izz>0.0998172</izz>
          </inertia>
        </inertial>
        <collision name='base_link_fixed_joint_lump__base_footprint_collision'>
          <pose>0 0 0.07 0 -0 0</pose>
          <geometry>
            <cylinder>
              <length>0.11</length>
              <radius>0.125</radius>
            </cylinder>
          </geometry>
          <max_contacts>10</max_contacts>
          <surface>
            <contact>
              <ode/>
            </contact>
            <bounce/>
            <friction>
              <torsional>
                <ode/>
              </torsional>
              <ode/>
            </friction>
          </surface>
        </collision>
        <collision name='base_link_fixed_joint_lump__ball_1_collision_1'>
          <pose>-0.1 0 0.0275 0 -0 0</pose>
          <geometry>
            <sphere>
              <radius>0.035</radius>
            </sphere>
          </geometry>
          <max_contacts>10</max_contacts>
          <surface>
            <contact>
              <ode/>
            </contact>
            <bounce/>
            <friction>
              <torsional>
                <ode/>
              </torsional>
              <ode/>
            </friction>
          </surface>
        </collision>
        <collision name='base_link_fixed_joint_lump__ball_2_collision_2'>
          <pose>0.1 0 0.0275 0 -0 0</pose>
          <geometry>
            <sphere>
              <radius>0.035</radius>
            </sphere>
          </geometry>
          <max_contacts>10</max_contacts>
          <surface>
            <contact>
              <ode/>
            </contact>
            <bounce/>
            <friction>
              <torsional>
                <ode/>
              </torsional>
              <ode/>
            </friction>
          </surface>
        </collision>
        <collision name='base_link_fixed_joint_lump__imu_collision_3'>
          <pose>0.05 0.058 0.03 0 -0 0</pose>
          <geometry>
            <box>
              <size>0.006 0.004 0.008</size>
            </box>
          </geometry>
          <max_contacts>10</max_contacts>
          <surface>
            <contact>
              <ode/>
            </contact>
            <bounce/>
            <friction>
              <torsional>
                <ode/>
              </torsional>
              <ode/>
            </friction>
          </surface>
        </collision>
        <collision name='base_link_fixed_joint_lump__marvelmind_collision_4'>
          <pose>-0.091 0 0.143 0 -0 0</pose>
          <geometry>
            <box>
              <size>0.06 0.06 0.03</size>
            </box>
          </geometry>
          <max_contacts>10</max_contacts>
          <surface>
            <contact>
              <ode/>
            </contact>
            <bounce/>
            <friction>
              <torsional>
                <ode/>
              </torsional>
              <ode/>
            </friction>
          </surface>
        </collision>
        <collision name='base_link_fixed_joint_lump__lidar_link_collision_5'>
          <pose>0 0 0.143 0 -0 1.5708</pose>
          <geometry>
            <cylinder>
              <length>0.18</length>
              <radius>0.0508</radius>
            </cylinder>
          </geometry>
          <max_contacts>10</max_contacts>
          <surface>
            <contact>
              <ode/>
            </contact>
            <bounce/>
            <friction>
              <torsional>
                <ode/>
              </torsional>
              <ode/>
            </friction>
          </surface>
        </collision>
        <visual name='base_link_fixed_joint_lump__base_footprint_visual'>
          <pose>0 0 0.07 0 -0 0</pose>
          <geometry>
            <cylinder>
              <length>0.11</length>
              <radius>0.125</radius>
            </cylinder>
          </geometry>
        </visual>
        <visual name='base_link_fixed_joint_lump__ball_1_visual_1'>
          <pose>-0.1 0 0.0275 1.5707 -0 0</pose>
          <geometry>
            <sphere>
              <radius>0.035</radius>
            </sphere>
          </geometry>
        </visual>
        <visual name='base_link_fixed_joint_lump__ball_2_visual_2'>
          <pose>0.1 0 0.0275 1.5707 -0 0</pose>
          <geometry>
            <sphere>
              <radius>0.035</radius>
            </sphere>
          </geometry>
        </visual>
        <visual name='base_link_fixed_joint_lump__imu_visual_3'>
          <pose>0.05 0.058 0.03 0 -0 0</pose>
          <geometry>
            <box>
              <size>0.0038 0.0052 0.00113</size>
            </box>
          </geometry>
        </visual>
        <visual name='base_link_fixed_joint_lump__marvelmind_visual_4'>
          <pose>-0.091 0 0.143 0 -0 0</pose>
          <geometry>
            <box>
              <size>0.06 0.06 0.03</size>
            </box>
          </geometry>
        </visual>
        <visual name='base_link_fixed_joint_lump__lidar_link_visual_5'>
          <pose>0 0 0.143 0 -0 1.5708</pose>
          <geometry>
            <cylinder>
              <length>0.18</length>
              <radius>0.0508</radius>
            </cylinder>
          </geometry>
        </visual>
        <self_collide>0</self_collide>
        <enable_wind>0</enable_wind>
        <kinematic>0</kinematic>
      </link>
      <joint name='joint_wheel_left' type='revolute'>
        <pose relative_to='base_link'>0 -0.115 0.0275 0 -0 0</pose>
        <parent>base_link</parent>
        <child>left_wheel</child>
        <axis>
          <xyz>1 0 0</xyz>
          <limit>
            <lower>-1e+16</lower>
            <upper>1e+16</upper>
          </limit>
          <dynamics>
            <spring_reference>0</spring_reference>
            <spring_stiffness>0</spring_stiffness>
          </dynamics>
        </axis>
      </joint>
      <link name='left_wheel'>
        <pose relative_to='joint_wheel_left'>0 0 0 0 -0 0</pose>
        <inertial>
          <pose>0 0 0 0 -0 0</pose>
          <mass>0.5</mass>
          <inertia>
            <ixx>0.0008</ixx>
            <ixy>0</ixy>
            <ixz>0</ixz>
            <iyy>0.0008</iyy>
            <iyz>0</iyz>
            <izz>0.000266</izz>
          </inertia>
        </inertial>
        <collision name='left_wheel_collision'>
          <pose>0 0 0 1.5707 -0 0</pose>
          <geometry>
            <cylinder>
              <length>0.02</length>
              <radius>0.035</radius>
            </cylinder>
          </geometry>
          <surface>
            <contact>
              <ode>
                <kp>1e+07</kp>
                <kd>1</kd>
              </ode>
            </contact>
            <friction>
              <ode>
                <mu>200</mu>
                <mu2>100</mu2>
                <fdir1>1 0 0</fdir1>
              </ode>
              <torsional>
                <ode/>
              </torsional>
            </friction>
            <bounce/>
          </surface>
          <max_contacts>10</max_contacts>
        </collision>
        <visual name='left_wheel_visual'>
          <pose>0 0 0 1.5707 -0 0</pose>
          <geometry>
            <cylinder>
              <length>0.02</length>
              <radius>0.035</radius>
            </cylinder>
          </geometry>
          <material>
            <script>
              <name>Gazebo/Black</name>
              <uri>file://media/materials/scripts/gazebo.material</uri>
            </script>
          </material>
        </visual>
        <self_collide>0</self_collide>
        <enable_wind>0</enable_wind>
        <kinematic>0</kinematic>
      </link>
      <joint name='joint_wheel_right' type='revolute'>
        <pose relative_to='base_link'>0 0.115 0.0275 0 -0 0</pose>
        <parent>base_link</parent>
        <child>right_wheel</child>
        <axis>
          <xyz>1 0 0</xyz>
          <limit>
            <lower>-1e+16</lower>
            <upper>1e+16</upper>
          </limit>
          <dynamics>
            <spring_reference>0</spring_reference>
            <spring_stiffness>0</spring_stiffness>
          </dynamics>
        </axis>
      </joint>
      <link name='right_wheel'>
        <pose relative_to='joint_wheel_right'>0 0 0 0 -0 0</pose>
        <inertial>
          <pose>0 0 0 0 -0 0</pose>
          <mass>0.5</mass>
          <inertia>
            <ixx>0.0008</ixx>
            <ixy>0</ixy>
            <ixz>0</ixz>
            <iyy>0.0008</iyy>
            <iyz>0</iyz>
            <izz>0.000266</izz>
          </inertia>
        </inertial>
        <collision name='right_wheel_collision'>
          <pose>0 0 0 1.5707 -0 0</pose>
          <geometry>
            <cylinder>
              <length>0.02</length>
              <radius>0.035</radius>
            </cylinder>
          </geometry>
          <surface>
            <contact>
              <ode>
                <kp>1e+07</kp>
                <kd>1</kd>
              </ode>
            </contact>
            <friction>
              <ode>
                <mu>200</mu>
                <mu2>100</mu2>
                <fdir1>1 0 0</fdir1>
              </ode>
              <torsional>
                <ode/>
              </torsional>
            </friction>
            <bounce/>
          </surface>
          <max_contacts>10</max_contacts>
        </collision>
        <visual name='right_wheel_visual'>
          <pose>0 0 0 1.5707 -0 0</pose>
          <geometry>
            <cylinder>
              <length>0.02</length>
              <radius>0.035</radius>
            </cylinder>
          </geometry>
          <material>
            <script>
              <name>Gazebo/Black</name>
              <uri>file://media/materials/scripts/gazebo.material</uri>
            </script>
          </material>
        </visual>
        <self_collide>0</self_collide>
        <enable_wind>0</enable_wind>
        <kinematic>0</kinematic>
      </link>
      <plugin name='gazebo_ros_diff_drive' filename='libgazebo_ros_diff_drive.so'>
        <alwaysOn>1</alwaysOn>
        <updateRate>10</updateRate>
        <max_wheel_torque>100</max_wheel_torque>
        <left_joint>joint_wheel_left</left_joint>
        <right_joint>joint_wheel_right</right_joint>
        <wheel_separation>0.0955</wheel_separation>
        <wheel_diameter>0.044</wheel_diameter>
        <command_topic>cmd_vel</command_topic>
        <publish_odom>1</publish_odom>
        <publish_odom_tf>1</publish_odom_tf>
        <publish_wheel_tf>1</publish_wheel_tf>
        <odometry_topic>odom</odometry_topic>
        <odometry_frame>odom</odometry_frame>
        <robot_base_frame>base_link</robot_base_frame>
        <ros>
          <namespace>Robot2</namespace>
        </ros>
      </plugin>
      <frame name='joint_ball_1' attached_to='base_footprint'>
        <pose>-0.1 0 -0.0425 0 -0 0</pose>
      </frame>
      <frame name='ball_1' attached_to='joint_ball_1'/>
      <frame name='joint_ball_2' attached_to='base_footprint'>
        <pose>0.1 0 -0.0425 0 -0 0</pose>
      </frame>
      <frame name='ball_2' attached_to='joint_ball_2'/>
      <frame name='joint_imu' attached_to='base_footprint'>
        <pose>0.05 0.058 -0.04 0 -0 0</pose>
      </frame>
      <frame name='imu' attached_to='joint_imu'/>
      <frame name='joint_base_link' attached_to='base_link'>
        <pose>0 0 0.07 0 -0 0</pose>
      </frame>
      <frame name='base_footprint' attached_to='joint_base_link'/>
      <frame name='joint_marv' attached_to='base_link'>
        <pose>-0.091 0 0.143 0 -0 0</pose>
      </frame>
      <frame name='marvelmind' attached_to='joint_marv'/>
      <frame name='lidar_joint' attached_to='base_link'>
        <pose>0 0 0.143 0 -0 1.5708</pose>
      </frame>
      <frame name='lidar_link' attached_to='lidar_joint'/>
      <pose>0.5 0 0 0 -0 1.5707</pose>
    </model>
  </world>
</sdf>
